<?xml version='1.0'?>
<sdf version='1.7'>
  <model name='pioneer2DX'>
    <link name='camera_link'>
    <inertial>
      <mass>0.1</mass>
      <inertia>
        <ixx>0.000166667</ixx>
        <iyy>0.000166667</iyy>
        <izz>0.000166667</izz>
        <ixy>0</ixy>
        <ixz>0</ixz>
        <iyz>0</iyz>
      </inertia>
    </inertial>
    <collision name='collision'>
      <geometry>
        <box>
          <size>0.1 0.1 0.1</size>
        </box>
      </geometry>
    </collision>
    <visual name='visual'>
      <geometry>
        <box>
          <size>0.1 0.1 0.1</size>
        </box>
      </geometry>
    </visual>
    <pose>0.189972 0 0.317326 0 -0 0</pose>
    <sensor name='camera' type='camera'>
      <camera>
        <horizontal_fov>1.047</horizontal_fov>
        <image>
          <width>960</width>
          <height>720</height>
        </image>
        <clip>
          <near>0.1</near>
          <far>100</far>
        </clip>
      </camera>
      <always_on>1</always_on>
      <update_rate>30</update_rate>
      <visualize>1</visualize>
      <plugin name="camera_controller" filename="libgazebo_ros_camera.so">
        <alwaysOn>true</alwaysOn>
        <updateRate>0.0</updateRate>
        <cameraName>camera1</cameraName>
        <imageTopicName>image_raw</imageTopicName>
        <cameraInfoTopicName>camera_info</cameraInfoTopicName>
        <frameName>camera_link</frameName>
        <hackBaseline>0.07</hackBaseline>
        <distortionK1>0.0</distortionK1>
        <distortionK2>0.0</distortionK2>
        <distortionK3>0.0</distortionK3>
        <distortionT1>0.0</distortionT1>
        <distortionT2>0.0</distortionT2>
      </plugin>
    </sensor>
         
    </link>
    <link name='chassis'>
    <pose>0 0 0.16 0 -0 0</pose>
    <inertial>
      <mass>5.67</mass>
      <inertia>
        <ixx>0.07</ixx>
        <iyy>0.08</iyy>
        <izz>0.1</izz>
        <ixy>0</ixy>
        <ixz>0</ixz>
        <iyz>0</iyz>
      </inertia>
    </inertial>
    <collision name='collision'>
      <geometry>
        <box>
          <size>0.445 0.277 0.17</size>
        </box>
      </geometry>
    </collision>
    <collision name='castor_collision'>
      <pose>-0.2 0 -0.12 0 -0 0</pose>
      <geometry>
        <sphere>
          <radius>0.04</radius>
        </sphere>
      </geometry>
      <surface>
        <friction>
          <ode>
            <mu>0</mu>
            <mu2>0</mu2>
            <slip1>1</slip1>
            <slip2>1</slip2>
          </ode>
        </friction>
      </surface>
    </collision>
    <visual name='visual'>
      <pose>0 0 0.04 0 -0 0</pose>
      <geometry>
        <mesh>
          <uri>model://pioneer2dx/meshes/chassis.dae</uri>
        </mesh>
      </geometry>
    </visual>
    <visual name='castor_visual'>
      <pose>-0.2 0 -0.12 0 -0 0</pose>
      <geometry>
        <sphere>
          <radius>0.04</radius>
        </sphere>
      </geometry>
      <material>
        <script>
          <uri>file://media/materials/scripts/gazebo.material</uri>
          <name>Gazebo/FlatBlack</name>
        </script>
      </material>
    </visual>
    </link>
    <link name='right_wheel'>
    <pose>0.1 -0.17 0.11 -0 1.5707 1.5707</pose>
    <inertial>
      <mass>1.5</mass>
      <inertia>
        <ixx>0.0051</ixx>
        <iyy>0.0051</iyy>
        <izz>0.009</izz>
        <ixy>0</ixy>
        <ixz>0</ixz>
        <iyz>0</iyz>
      </inertia>
    </inertial>
    <collision name='collision'>
      <geometry>
        <cylinder>
          <radius>0.11</radius>
          <length>0.05</length>
        </cylinder>
      </geometry>
      <surface>
        <friction>
          <ode>
            <mu>100000</mu>
            <mu2>100000</mu2>
            <slip1>0</slip1>
            <slip2>0</slip2>
          </ode>
        </friction>
      </surface>
    </collision>
    <visual name='visual'>
      <geometry>
        <cylinder>
          <radius>0.11</radius>
          <length>0.05</length>
        </cylinder>
      </geometry>
      <material>
        <script>
          <uri>file://media/materials/scripts/gazebo.material</uri>
          <name>Gazebo/FlatBlack</name>
        </script>
      </material>
    </visual>
    </link>
    <link name='left_wheel'>
    <pose>0.1 0.17 0.11 -0 1.5707 1.5707</pose>
    <inertial>
      <mass>1.5</mass>
      <inertia>
        <ixx>0.0051</ixx>
        <iyy>0.0051</iyy>
        <izz>0.009</izz>
        <ixy>0</ixy>
        <ixz>0</ixz>
        <iyz>0</iyz>
      </inertia>
    </inertial>
    <collision name='collision'>
      <geometry>
        <cylinder>
          <radius>0.11</radius>
          <length>0.05</length>
        </cylinder>
      </geometry>
      <surface>
        <friction>
          <ode>
            <mu>100000</mu>
            <mu2>100000</mu2>
            <slip1>0</slip1>
            <slip2>0</slip2>
          </ode>
        </friction>
      </surface>
    </collision>
    <visual name='visual'>
      <geometry>
        <cylinder>
          <radius>0.11</radius>
          <length>0.05</length>
        </cylinder>
      </geometry>
      <material>
        <script>
          <uri>file://media/materials/scripts/gazebo.material</uri>
          <name>Gazebo/FlatBlack</name>
        </script>
      </material>
    </visual>
    </link>
    <joint name='left_wheel_hinge' type='revolute'>
    <pose>0 0 -0.03 0 -0 0</pose>
    <child>left_wheel</child>
    <parent>chassis</parent>
    <axis>
      <xyz expressed_in='__model__'>0 1 0</xyz>
      <limit>
        <lower>-1e+16</lower>
        <upper>1e+16</upper>
      </limit>
    </axis>
    </joint>
    <joint name='right_wheel_hinge' type='revolute'>
    <pose>0 0 0.03 0 -0 0</pose>
    <child>right_wheel</child>
    <parent>chassis</parent>
    <axis>
      <xyz expressed_in='__model__'>0 1 0</xyz>
      <limit>
        <lower>-1e+16</lower>
        <upper>1e+16</upper>
      </limit>
    </axis>
    </joint>
    <!-- <plugin name='diff_drive' filename='libDiffDrivePlugin.so'>
    <left_joint>left_wheel_hinge</left_joint>
    <right_joint>right_wheel_hinge</right_joint>
    <torque>5</torque>
    </plugin> -->


    <!-- <pose>-0.094986 -0.001039 -0.158663 0 -0 0</pose> -->
    <!-- <pose>-0.094986 -0.001039 0.098663 0 -0 0</pose> -->
    <!-- <pose>0 0  0 -0 0</pose> -->
      
    
    <plugin name='differential_drive_controller'
              filename='libgazebo_ros_diff_drive.so'>
        <alwaysOn>true</alwaysOn>
        <updateRate>100</updateRate>
        <leftJoint>left_wheel_hinge</leftJoint>
        <rightJoint>right_wheel_hinge</rightJoint>
        <wheelSeparation>0.39</wheelSeparation>
        <wheelDiameter>0.15</wheelDiameter>
        <torque>5</torque>
        <commandTopic>cmd_vel</commandTopic>
        <odometryTopic>odom</odometryTopic>
        <odometryFrame>odom</odometryFrame>
        <robotBaseFrame>chassis</robotBaseFrame>
    </plugin>
    <joint name='chassis_JOINT_0' type='fixed'>
      <parent>chassis</parent>
      <child>camera_link</child>
      <pose>0 0 0 0 -0 0</pose>
      <physics>
        <ode>
          <limit>
            <cfm>0</cfm>
            <erp>0.2</erp>
          </limit>
          <suspension>
            <cfm>0</cfm>
            <erp>0.2</erp>
          </suspension>
        </ode>
      </physics>
    </joint>
    <static>0</static>
    <allow_auto_disable>1</allow_auto_disable>
  </model>
</sdf>
